Workbook

Sheet Executive Summary
A1: Hero MotoCorp | Integrated 3-Statement + FCFF DCF Model
A3: Model status | B3: MODEL-CHECKED — forecast formula/reconciliation checks are zero; historical source-data discrepancies are disclosed below.
A5: Key valuation outputs
A6: WACC | B6: =WACC!C23 -> 0.10232198
A7: Terminal growth | B7: =FCFF!C17 -> 0.05
A8: Enterprise value (Rs Cr) | B8: =FCFF!C20 -> 156036.84
A9: Equity value (Rs Cr) | B9: =FCFF!C25 -> 170283.65
A10: Intrinsic value/share (Rs) | B10: =FCFF!C27 -> 8514.1823
A11: Reference market price (Rs) | B11: =FCFF!C29 -> 5000
A12: Model-implied upside/(downside) | B12: =FCFF!C30 -> 0.70283647
A15: Key modelling diagnostics
A16: FY24 source BS discrepancy (Rs Cr) | B16: ='Balance Sheet'!F57 -> -20.9
A17: FY25 source BS discrepancy (Rs Cr) | B17: ='Balance Sheet'!G57 -> -11.6
A18: FY26E-FY30E FCFF CAGR | B18: =(FCFF!G10/FCFF!C10)^(1/4)-1 -> 0.22098325
A19: Terminal value / Enterprise value | B19: =FCFF!C19/FCFF!C20 -> 0.83251346
A20: FY30E sales volume (lakh units) | B20: ='Revenue Model'!L4 -> 119
A21: FY25-FY30E revenue CAGR | B21: =('Revenue Model'!L7/'Revenue Model'!G7)^(1/5)-1 -> 0.2219697
A22: FY30E operating EBIT margin | B22: ='P&L'!L37 -> 0.12493858
A23: Historical D&A schedule mismatches | B23: FY22: Rs 25.60 Cr; FY23: Rs 40.00 Cr versus reported P&L D&A.
A25: Transparency note | B25: FY24 and FY25 source balance sheets do not fully reconcile (Rs 20.90 Cr and Rs 11.60 Cr residuals). FY26E onward is normalized for the FY25 opening mismatch; no historical source figure is silently overwritten.

Sheet Revenue Model
A1: Hero MotoCorp | Revenue Model
A2: All figures in Rs Crore unless stated
A3: Revenue driver | C3: FY21 | D3: FY22 | E3: FY23 | F3: FY24 | G3: FY25 | H3: FY26E | I3: FY27E | J3: FY28E | K3: FY29E | L3: FY30E
A4: Sales Volume (lakh units) | C4: 58 | D4: 49 | E4: 53 | F4: 56 | G4: 59 | H4: 68 | I4: 78 | J4: 89 | K4: 103 | L4: 119 | M4: FY30E volume is set at 119 lakh units in the model; the source note references 120 lakh units, but no 120-unit formula is used.
A5: Sales volume growth (%) | D5: =(D4-C4)/C4 -> -0.15517241 | E5: =(E4-D4)/D4 -> 0.081632653 | F5: =(F4-E4)/E4 -> 0.056603774 | G5: =(G4-F4)/F4 -> 0.053571429 | H5: =(H4-G4)/G4 -> 0.15254237 | I5: =(I4-H4)/H4 -> 0.14705882 | J5: =(J4-I4)/I4 -> 0.14102564 | K5: =(K4-J4)/J4 -> 0.15730337 | L5: =(L4-K4)/K4 -> 0.15533981 | M5: Historical/forecast volume growth is calculated from the explicit volume assumptions.
A6: Realisation inflation factor (x) | H6: 1.07 | I6: 1.06 | J6: 1.06 | K6: 1.06 | L6: 1.06
A7: Revenue from operations | C7: 30959.19 | D7: 29551.28 | E7: 34158.38 | F7: 37788.62 | G7: 40923.42 | H7: =H4*H16/100 -> 50467.594 | I7: =I4*I16/100 -> 61362.657 | J7: =J4*J16/100 -> 74217.347 | K7: =K4*K16/100 -> 91045.505 | L7: =L4*L16/100 -> 111499.81 | M7: Revenue = volume × blended realisation; forecast realisation grows by the explicit inflation factor.
A8: Other income | C8: 557.9 | D8: 555.01 | E8: 569.01 | F8: 854.54 | G8: 1044.08 | H8: =H7*Assumptions!H12 -> 1089.8426 | I8: =I7*Assumptions!I12 -> 1325.1204 | J8: =J7*Assumptions!J12 -> 1602.7161 | K8: =K7*Assumptions!K12 -> 1966.1185 | L8: =L7*Assumptions!L12 -> 2407.827 | M8: Forecast using normalized FY23-FY25 other-income/revenue ratio.
A9: Total income | C9: =SUM(C7:C8) -> 31517.09 | D9: =SUM(D7:D8) -> 30106.29 | E9: =SUM(E7:E8) -> 34727.39 | F9: =SUM(F7:F8) -> 38643.16 | G9: =SUM(G7:G8) -> 41967.5 | H9: =SUM(H7:H8) -> 51557.436 | I9: =SUM(I7:I8) -> 62687.777 | J9: =SUM(J7:J8) -> 75820.063 | ... L9: =SUM(L7:L8) -> 113907.63
A11: Revenue split — domestic vs export
A13: Export volume (lakh units) | C13: 1.6 | D13: 2.2 | E13: 1.73 | F13: 2.01 | G13: 2.87 | H13: =H4*H15 -> 2.7701875 | I13: =I4*I15 -> 3.2940705 | J13: =J4*J15 -> 3.6340416 | K13: =K4*K15 -> 4.2775664 | L13: =L4*L15 -> 5.0007211
A14: Domestic volume (lakh units) | C14: =C4-C13 -> 56.4 | D14: =D4-D13 -> 46.8 | E14: =E4-E13 -> 51.27 | F14: =F4-F13 -> 53.99 | G14: =G4-G13 -> 56.13 | H14: =H4-H13 -> 65.229812 | I14: =I4-I13 -> 74.705929 | J14: =J4-J13 -> 85.365958 | ... L14: =L4-L13 -> 113.99928
A15: Export share of volume (%) | C15: =C13/C4 -> 0.027586207 | D15: =D13/D4 -> 0.044897959 | E15: =E13/E4 -> 0.032641509 | F15: =F13/F4 -> 0.035892857 | G15: =G13/G4 -> 0.048644068 | H15: =G15*0.4+F15*0.3+E15*0.1+D15*0.1+C15*0.1 -> 0.040738052 | I15: =H15*0.4+G15*0.3+F15*0.1+E15*0.1+D15*0.1 -> 0.042231674 | J15: =I15*0.4+H15*0.3+G15*0.1+F15*0.1+E15*0.1 -> 0.040831928 | K15: =J15*0.4+I15*0.3+H15*0.1+G15*0.1+F15*0.1 -> 0.041529771 | L15: =K15*0.4+J15*0.3+I15*0.1+H15*0.1+G15*0.1 -> 0.042022866
A16: Realisation per vehicle (Rs) | C16: =C7/C4*100 -> 53377.914 | D16: =D7/D4*100 -> 60308.735 | E16: =E7/E4*100 -> 64449.774 | F16: =F7/F4*100 -> 67479.679 | G16: =G7/G4*100 -> 69361.729 | H16: =G16*H6 -> 74217.05 | I16: =H16*I6 -> 78670.073 | J16: =I16*J6 -> 83390.277 | K16: =J16*K6 -> 88393.694 | L16: =K16*L6 -> 93697.315
A17: Domestic revenue | C17: =C16*C14/100 -> 30105.143 | D17: =D16*D14/100 -> 28224.488 | E17: =E16*E14/100 -> 33043.399 | F17: =F16*F14/100 -> 36432.278 | G17: =G16*G14/100 -> 38932.738 | H17: =H16*H14/100 -> 48411.642 | I17: =I16*I14/100 -> 58771.209 | J17: =J16*J14/100 -> 71186.909 | ... L17: =L16*L14/100 -> 106814.26
A18: Export revenue | C18: =C16*C13/100 -> 854.04662 | D18: =D16*D13/100 -> 1326.7922 | E18: =E16*E13/100 -> 1114.9811 | F18: =F16*F13/100 -> 1356.3415 | G18: =G16*G13/100 -> 1990.6816 | H18: =H16*H13/100 -> 2055.9515 | I18: =I16*I13/100 -> 2591.4477 | J18: =J16*J13/100 -> 3030.4374 | ... L18: =L16*L13/100 -> 4685.5414
A19: Total revenue (check = row 7) | C19: =SUM(C17:C18) -> 30959.19 | D19: =SUM(D17:D18) -> 29551.28 | E19: =SUM(E17:E18) -> 34158.38 | F19: =SUM(F17:F18) -> 37788.62 | G19: =SUM(G17:G18) -> 40923.42 | H19: =SUM(H17:H18) -> 50467.594 | I19: =SUM(I17:I18) -> 61362.657 | J19: =SUM(J17:J18) -> 74217.347 | ... L19: =SUM(L17:L18) -> 111499.81
A21: Modeling note | B21: Forecast volumes and realization factors are explicit model assumptions retained from the supplied workbook; revenue is built from volume × blended realization.
A22: Export Volume - the part and vehicle that are sold outside india | M22: Export volume represents two-wheeler units modelled as sold outside India.

Sheet Assumptions
A1: Hero MotoCorp | P&L Assumptions | M1: Reason
A3: Years | C3: FY21 | D3: FY22 | E3: FY23 | F3: FY24 | G3: FY25 | H3: FY26E | I3: FY27E | J3: FY28E | K3: FY29E | L3: FY30E
A4: Cost of materials (% of revenue) | C4: ='P&L'!C10/'P&L'!C5 -> 0.70958058 | D4: ='P&L'!D10/'P&L'!D5 -> 0.70540904 | E4: ='P&L'!E10/'P&L'!E5 -> 0.70437445 | F4: ='P&L'!F10/'P&L'!F5 -> 0.65725846 | G4: ='P&L'!G10/'P&L'!G5 -> 0.65016731 | H4: =AVERAGE($E$4:$G$4) -> 0.67060007 | I4: =AVERAGE($E$4:$G$4) -> 0.67060007 | J4: =AVERAGE($E$4:$G$4) -> 0.67060007 | K4: =AVERAGE($E$4:$G$4) -> 0.67060007 | L4: =AVERAGE($E$4:$G$4) -> 0.67060007 | M4: Normalized using FY23-FY25 average.
A5: Purchase of stock-in-trade (% of revenue) | C5: ='P&L'!C11/'P&L'!C5 -> 0.0010058403 | D5: ='P&L'!D11/'P&L'!D5 -> 0.0015549242 | E5: ='P&L'!E11/'P&L'!E5 -> 0.0013885319 | F5: ='P&L'!F11/'P&L'!F5 -> 0.012813381 | G5: ='P&L'!G11/'P&L'!G5 -> 0.013388666 | H5: =AVERAGE($E$5:$G$5) -> 0.0091968597 | I5: =AVERAGE($E$5:$G$5) -> 0.0091968597 | J5: =AVERAGE($E$5:$G$5) -> 0.0091968597 | K5: =AVERAGE($E$5:$G$5) -> 0.0091968597 | L5: =AVERAGE($E$5:$G$5) -> 0.0091968597 | M5: Normalized using FY23-FY25 average.
A6: Change in inventories (% of revenue) | C6: ='P&L'!C12/'P&L'!C5 -> -0.0082550609 | D6: ='P&L'!D12/'P&L'!D5 -> 0.00097017794 | E6: ='P&L'!E12/'P&L'!E5 -> -0.0047920891 | F6: ='P&L'!F12/'P&L'!F5 -> 0.0049843048 | G6: ='P&L'!G12/'P&L'!G5 -> -0.0059706642 | H6: =AVERAGE($E$6:$G$6) -> -0.0019261495 | I6: =AVERAGE($E$6:$G$6) -> -0.0019261495 | J6: =AVERAGE($E$6:$G$6) -> -0.0019261495 | K6: =AVERAGE($E$6:$G$6) -> -0.0019261495 | L6: =AVERAGE($E$6:$G$6) -> -0.0019261495 | M6: Normalized using FY23-FY25 average.
A7: Employee benefits (% of revenue) | C7: ='P&L'!C14/'P&L'!C5 -> 0.063019091 | D7: ='P&L'!D14/'P&L'!D5 -> 0.067536161 | E7: ='P&L'!E14/'P&L'!E5 -> 0.065871098 | F7: ='P&L'!F14/'P&L'!F5 -> 0.065404611 | G7: ='P&L'!G14/'P&L'!G5 -> 0.065489883 | H7: =AVERAGE($E$7:$G$7) -> 0.065588531 | I7: =AVERAGE($E$7:$G$7) -> 0.065588531 | J7: =AVERAGE($E$7:$G$7) -> 0.065588531 | K7: =AVERAGE($E$7:$G$7) -> 0.065588531 | L7: =AVERAGE($E$7:$G$7) -> 0.065588531 | M7: Normalized using FY23-FY25 average.
A8: Other expenses (% of revenue) | C8: ='P&L'!C17/'P&L'!C5 -> 0.10223297 | D8: ='P&L'!D17/'P&L'!D5 -> 0.10796047 | E8: ='P&L'!E17/'P&L'!E5 -> 0.11331129 | F8: ='P&L'!F17/'P&L'!F5 -> 0.11797202 | G8: ='P&L'!G17/'P&L'!G5 -> 0.13163294 | H8: =AVERAGE($E$8:$G$8) -> 0.12097208 | I8: =AVERAGE($E$8:$G$8) -> 0.12097208 | J8: =AVERAGE($E$8:$G$8) -> 0.12097208 | K8: =AVERAGE($E$8:$G$8) -> 0.12097208 | L8: =AVERAGE($E$8:$G$8) -> 0.12097208 | M8: Normalized using FY23-FY25 average.
M9: -/-
A10: Share of associates (Rs Cr) | C10: ='P&L'!C21 -> -46.56 | D10: ='P&L'!D21 -> -199.05 | E10: ='P&L'!E21 -> 3.11 | F10: ='P&L'!F21 -> -120.25 | G10: ='P&L'!G21 -> -161.12 | H10: =AVERAGE($E$10:$G$10) -> -92.753333 | I10: =AVERAGE($E$10:$G$10) -> -92.753333 | J10: =AVERAGE($E$10:$G$10) -> -92.753333 | K10: =AVERAGE($E$10:$G$10) -> -92.753333 | L10: =AVERAGE($E$10:$G$10) -> -92.753333 | M10: Normalized using FY23-FY25 average.
A11: Effective tax rate (%) | C11: ='P&L'!C30/'P&L'!C24 -> 0.23725489 | D11: ='P&L'!D30/'P&L'!D24 -> 0.23840215 | E11: ='P&L'!E30/'P&L'!E24 -> 0.27531693 | F11: ='P&L'!F30/'P&L'!F24 -> 0.26483046 | G11: ='P&L'!G30/'P&L'!G24 -> 0.26253211 | H11: =AVERAGE($E$11:$G$11) -> 0.26755983 | I11: =AVERAGE($E$11:$G$11) -> 0.26755983 | J11: =AVERAGE($E$11:$G$11) -> 0.26755983 | K11: =AVERAGE($E$11:$G$11) -> 0.26755983 | L11: =AVERAGE($E$11:$G$11) -> 0.26755983 | M11: Normalized effective tax rate using FY23-FY25 average.
A12: Other income (% of revenue) | C12: ='P&L'!C6/'P&L'!C5 -> 0.018020497 | D12: ='P&L'!D6/'P&L'!D5 -> 0.018781251 | E12: ='P&L'!E6/'P&L'!E5 -> 0.016657991 | F12: ='P&L'!F6/'P&L'!F5 -> 0.022613686 | G12: ='P&L'!G6/'P&L'!G5 -> 0.025513019 | H12: =AVERAGE($E$12:$G$12) -> 0.021594899 | I12: =AVERAGE($E$12:$G$12) -> 0.021594899 | J12: =AVERAGE($E$12:$G$12) -> 0.021594899 | K12: =AVERAGE($E$12:$G$12) -> 0.021594899 | L12: =AVERAGE($E$12:$G$12) -> 0.021594899 | M12: Normalized at FY23-FY25 average; used to forecast non-operating other income.
A15: Modeling note | B15: Forecast operating ratios and tax are normalized to FY23-FY25 averages to avoid rolling-average drift.

Sheet Schedules
A1: Hero MotoCorp | Supporting Schedules | M1: Reasons
A2: Working Capital Schedule | C2: FY21 | D2: FY22 | E2: FY23 | F2: FY24 | G2: FY25 | H2: FY26E | I2: FY27E | J2: FY28E | K2: FY29E | L2: FY30E
A3: Current assets (excluding cash)
A4: Inventories | C4: ='Balance Sheet'!C19 -> 1789.27 | D4: ='Balance Sheet'!D19 -> 1472.41 | E4: ='Balance Sheet'!E19 -> 1756.39 | F4: ='Balance Sheet'!F19 -> 1755.9 | G4: ='Balance Sheet'!G19 -> 2013.34 | H4: =H25*'Revenue Model'!H7/365 -> 2474.3104 | I4: =I25*'Revenue Model'!I7/365 -> 3008.4704 | J4: =J25*'Revenue Model'!J7/365 -> 3638.7064 | K4: =K25*'Revenue Model'!K7/365 -> 4463.7524 | L4: =L25*'Revenue Model'!L7/365 -> 5466.5799 | M4: Forecast inventory is driven by normalized inventory days applied to revenue.
A5: Investments (current) | C5: ='Balance Sheet'!C21 -> 6225.34 | D5: ='Balance Sheet'!D21 -> 5870.31 | E5: ='Balance Sheet'!E21 -> 3671.85 | F5: ='Balance Sheet'!F21 -> 4305.08 | G5: ='Balance Sheet'!G21 -> 6635.99 | H5: =$G$5 -> 6635.99 | I5: =$G$5 -> 6635.99 | J5: =$G$5 -> 6635.99 | K5: =$G$5 -> 6635.99 | L5: =$G$5 -> 6635.99
A6: Trade receivables | C6: ='Balance Sheet'!C22 -> 2274.68 | D6: ='Balance Sheet'!D22 -> 2158.49 | E6: ='Balance Sheet'!E22 -> 2719.47 | F6: ='Balance Sheet'!F22 -> 2630.22 | G6: ='Balance Sheet'!G22 -> 3381.29 | H6: =H27*'Revenue Model'!H7/365 -> 3900.167 | I6: =I27*'Revenue Model'!I7/365 -> 4742.1442 | J6: =J27*'Revenue Model'!J7/365 -> 5735.5626 | K6: =K27*'Revenue Model'!K7/365 -> 7036.0531 | L6: =L27*'Revenue Model'!L7/365 -> 8616.7742
A7: Bank balances (other than cash) | C7: ='Balance Sheet'!C24 -> 121.62 | D7: ='Balance Sheet'!D24 -> 118.72 | E7: ='Balance Sheet'!E24 -> 196.5 | F7: ='Balance Sheet'!F24 -> 91.56 | G7: ='Balance Sheet'!G24 -> 190.53 | H7: =$G$7 -> 190.53 | I7: =$G$7 -> 190.53 | J7: =$G$7 -> 190.53 | K7: =$G$7 -> 190.53 | L7: =$G$7 -> 190.53
A8: Loans (current) | C8: ='Balance Sheet'!C25 -> 39.77 | D8: ='Balance Sheet'!D25 -> 22.81 | E8: ='Balance Sheet'!E25 -> 23.71 | F8: ='Balance Sheet'!F25 -> 24.56 | G8: ='Balance Sheet'!G25 -> 27.07 | H8: =$G$8 -> 27.07 | I8: =$G$8 -> 27.07 | J8: =$G$8 -> 27.07 | K8: =$G$8 -> 27.07 | L8: =$G$8 -> 27.07
A9: Other financial assets (current) | C9: ='Balance Sheet'!C26 -> 365.73 | D9: ='Balance Sheet'!D26 -> 475 | E9: ='Balance Sheet'!E26 -> 571.65 | F9: ='Balance Sheet'!F26 -> 423.53 | G9: ='Balance Sheet'!G26 -> 141.59 | H9: =$G$9 -> 141.59 | I9: =$G$9 -> 141.59 | J9: =$G$9 -> 141.59 | K9: =$G$9 -> 141.59 | L9: =$G$9 -> 141.59
A10: Other current assets | C10: ='Balance Sheet'!C27 -> 279.45 | D10: ='Balance Sheet'!D27 -> 273.46 | E10: ='Balance Sheet'!E27 -> 269.46 | F10: ='Balance Sheet'!F27 -> 479.69 | G10: ='Balance Sheet'!G27 -> 462.41 | H10: =H31*'Revenue Model'!H7/365 -> 536.33558 | I10: =I31*'Revenue Model'!I7/365 -> 652.12097 | J10: =J31*'Revenue Model'!J7/365 -> 788.73195 | K10: =K31*'Revenue Model'!K7/365 -> 967.57027 | L10: =L31*'Revenue Model'!L7/365 -> 1184.9448
A11: Income tax assets (current) | C11: ='Balance Sheet'!C28 -> 0 | D11: ='Balance Sheet'!D28 -> 0 | E11: ='Balance Sheet'!E28 -> 0 | F11: ='Balance Sheet'!F28 -> 0 | G11: ='Balance Sheet'!G28 -> 198.12 | H11: =$G$11 -> 198.12 | I11: =$G$11 -> 198.12 | J11: =$G$11 -> 198.12 | K11: =$G$11 -> 198.12 | L11: =$G$11 -> 198.12
A12: Total current assets (ex-cash) | C12: =SUM(C4:C11) -> 11095.86 | D12: =SUM(D4:D11) -> 10391.2 | E12: =SUM(E4:E11) -> 9209.03 | F12: =SUM(F4:F11) -> 9710.54 | G12: =SUM(G4:G11) -> 13050.34 | H12: =SUM(H4:H11) -> 14104.113 | I12: =SUM(I4:I11) -> 15596.036 | J12: =SUM(J4:J11) -> 17356.301 | ... L12: =SUM(L4:L11) -> 22461.599
A13: Current liabilities
A14: Borrowings (short-term) | C14: ='Balance Sheet'!C48 -> 285.16 | D14: ='Balance Sheet'!D48 -> 317.31 | E14: ='Balance Sheet'!E48 -> 293.15 | F14: ='Balance Sheet'!F48 -> 363.43 | G14: ='Balance Sheet'!G48 -> 456.76 | H14: =$G$14 -> 456.76 | I14: =$G$14 -> 456.76 | J14: =$G$14 -> 456.76 | K14: =$G$14 -> 456.76 | L14: =$G$14 -> 456.76 | M14: values are extracted from revneue model
A15: Lease liabilities (short-term) | C15: ='Balance Sheet'!C49 -> 29.57 | D15: ='Balance Sheet'!D49 -> 36.18 | E15: ='Balance Sheet'!E49 -> 34.63 | F15: ='Balance Sheet'!F49 -> 43.85 | G15: ='Balance Sheet'!G49 -> 46.96 | H15: =$G$15 -> 46.96 | I15: =$G$15 -> 46.96 | J15: =$G$15 -> 46.96 | K15: =$G$15 -> 46.96 | L15: =$G$15 -> 46.96
A16: Trade payables | C16: ='Balance Sheet'!C50 -> 5264.18 | D16: ='Balance Sheet'!D50 -> 4343.09 | E16: ='Balance Sheet'!E50 -> 4760.14 | F16: ='Balance Sheet'!F50 -> 5622.9 | G16: ='Balance Sheet'!G50 -> 5699.66 | H16: =H35*('P&L'!H10+'P&L'!H11+'P&L'!H12)/365 -> 7195.913 | I16: =I35*('P&L'!I10+'P&L'!I11+'P&L'!I12)/365 -> 8749.3837 | J16: =J35*('P&L'!J10+'P&L'!J11+'P&L'!J12)/365 -> 10582.267 | K16: =K35*('P&L'!K10+'P&L'!K11+'P&L'!K12)/365 -> 12981.707 | L16: =L35*('P&L'!L10+'P&L'!L11+'P&L'!L12)/365 -> 15898.18
A17: Other financial liabilities (current) | C17: ='Balance Sheet'!C51 -> 179.21 | D17: ='Balance Sheet'!D51 -> 145.58 | E17: ='Balance Sheet'!E51 -> 169.93 | F17: ='Balance Sheet'!F51 -> 254.9 | G17: ='Balance Sheet'!G51 -> 282.94 | H17: =$G$17 -> 282.94 | I17: =$G$17 -> 282.94 | J17: =$G$17 -> 282.94 | K17: =$G$17 -> 282.94 | L17: =$G$17 -> 282.94
A18: Other current liabilities | C18: ='Balance Sheet'!C52 -> 570.59 | D18: ='Balance Sheet'!D52 -> 496.32 | E18: ='Balance Sheet'!E52 -> 562.09 | F18: ='Balance Sheet'!F52 -> 603.85 | G18: ='Balance Sheet'!G52 -> 768.17 | H18: =H37*'Revenue Model'!H7/365 -> 861.41451 | I18: =I37*'Revenue Model'!I7/365 -> 1047.3787 | J18: =J37*'Revenue Model'!J7/365 -> 1266.7911 | K18: =K37*'Revenue Model'!K7/365 -> 1554.0253 | L18: =L37*'Revenue Model'!L7/365 -> 1903.1529
A19: Provisions (current) | C19: ='Balance Sheet'!C53 -> 175.82 | D19: ='Balance Sheet'!D53 -> 179.15 | E19: ='Balance Sheet'!E53 -> 192.68 | F19: ='Balance Sheet'!F53 -> 159.44 | G19: ='Balance Sheet'!G53 -> 221.49 | H19: =H38*'Revenue Model'!H7/365 -> 256.91953 | I19: =I38*'Revenue Model'!I7/365 -> 312.38392 | J19: =J38*'Revenue Model'!J7/365 -> 377.82435 | K19: =K38*'Revenue Model'!K7/365 -> 463.49284 | L19: =L38*'Revenue Model'!L7/365 -> 567.62123
A20: Total current liabilities | C20: =SUM(C14:C19) -> 6504.53 | D20: =SUM(D14:D19) -> 5517.63 | E20: =SUM(E14:E19) -> 6012.62 | F20: =SUM(F14:F19) -> 7048.37 | G20: =SUM(G14:G19) -> 7475.98 | H20: =SUM(H14:H19) -> 9100.9071 | I20: =SUM(I14:I19) -> 10895.806 | J20: =SUM(J14:J19) -> 13013.543 | ... L20: =SUM(L14:L19) -> 19155.614
A21: Operating net working capital | C21: =C4+C6+C10+C11-C16-C18-C19 -> -1667.19 | D21: =D4+D6+D10+D11-D16-D18-D19 -> -1114.2 | E21: =E4+E6+E10+E11-E16-E18-E19 -> -769.59 | F21: =F4+F6+F10+F11-F16-F18-F19 -> -1520.38 | G21: =G4+G6+G10+G11-G16-G18-G19 -> -634.16 | H21: =H4+H6+H10+H11-H16-H18-H19 -> -1205.3141 | I21: =I4+I6+I10+I11-I16-I18-I19 -> -1508.2907 | J21: =J4+J6+J10+J11-J16-J18-J19 -> -1865.7619 | ... L21: =L4+L6+L10+L11-L16-L18-L19 -> -2902.5355 | M21: Excludes cash, investments, loans, borrowings, lease liabilities and other financing-related balances.
A22: Change in operating net working capital | D22: =D21-C21 -> 552.99 | E22: =E21-D21 -> 344.61 | F22: =F21-E21 -> -750.79 | G22: =G21-F21 -> 886.22 | H22: =H21-G21 -> -571.15406 | I22: =I21-H21 -> -302.97665 | J22: =J21-I21 -> -357.47117 | K22: =K21-J21 -> -467.96782 | L22: =L21-K21 -> -568.80584
A24: Days of revenue (item x 365 / revenue)
A25: Inventories | C25: =C4*365/'Revenue Model'!C7 -> 21.094982 | D25: =D4*365/'Revenue Model'!D7 -> 18.186341 | E25: =E4*365/'Revenue Model'!E7 -> 18.767938 | F25: =F4*365/'Revenue Model'!F7 -> 16.960225 | G25: =G4*365/'Revenue Model'!G7 -> 17.957177 | H25: =AVERAGE($E$25:$G$25) -> 17.895113 | I25: =AVERAGE($E$25:$G$25) -> 17.895113 | J25: =AVERAGE($E$25:$G$25) -> 17.895113 | K25: =AVERAGE($E$25:$G$25) -> 17.895113 | L25: =AVERAGE($E$25:$G$25) -> 17.895113 | M25: I have taken weighted average here and gave more important to recent data
A26: Investments (current) | C26: =C5*365/'Revenue Model'!C7 -> 73.394979 | D26: =D5*365/'Revenue Model'!D7 -> 72.506611 | E26: =E5*365/'Revenue Model'!E7 -> 39.235621 | F26: =F5*365/'Revenue Model'!F7 -> 41.582736 | G26: =G5*365/'Revenue Model'!G7 -> 59.187046 | H26: =$G$26 -> 59.187046 | I26: =$G$26 -> 59.187046 | J26: =$G$26 -> 59.187046 | K26: =$G$26 -> 59.187046 | L26: =$G$26 -> 59.187046
A27: Trade receivables | C27: =C6*365/'Revenue Model'!C7 -> 26.817827 | D27: =D6*365/'Revenue Model'!D7 -> 26.660397 | E27: =E6*365/'Revenue Model'!E7 -> 29.058947 | F27: =F6*365/'Revenue Model'!F7 -> 25.405275 | G27: =G6*365/'Revenue Model'!G7 -> 30.158057 | H27: =AVERAGE($E$27:$G$27) -> 28.207427 | I27: =AVERAGE($E$27:$G$27) -> 28.207427 | J27: =AVERAGE($E$27:$G$27) -> 28.207427 | K27: =AVERAGE($E$27:$G$27) -> 28.207427 | L27: =AVERAGE($E$27:$G$27) -> 28.207427
A28: Bank balances (other than cash) | C28: =C7*365/'Revenue Model'!C7 -> 1.433865 | D28: =D7*365/'Revenue Model'!D7 -> 1.4663595 | E28: =E7*365/'Revenue Model'!E7 -> 2.0997044 | F28: =F7*365/'Revenue Model'!F7 -> 0.88437736 | G28: =G7*365/'Revenue Model'!G7 -> 1.6993558 | H28: =$G$28 -> 1.6993558 | I28: =$G$28 -> 1.6993558 | J28: =$G$28 -> 1.6993558 | K28: =$G$28 -> 1.6993558 | L28: =$G$28 -> 1.6993558
A29: Loans (current) | C29: =C8*365/'Revenue Model'!C7 -> 0.46887693 | D29: =D8*365/'Revenue Model'!D7 -> 0.28173568 | E29: =E8*365/'Revenue Model'!E7 -> 0.25335364 | F29: =F8*365/'Revenue Model'!F7 -> 0.23722486 | G29: =G8*365/'Revenue Model'!G7 -> 0.24143999 | H29: =$G$29 -> 0.24143999 | I29: =$G$29 -> 0.24143999 | J29: =$G$29 -> 0.24143999 | K29: =$G$29 -> 0.24143999 | L29: =$G$29 -> 0.24143999
A30: Other financial assets (current) | C30: =C9*365/'Revenue Model'!C7 -> 4.3118522 | D30: =D9*365/'Revenue Model'!D7 -> 5.8669201 | E30: =E9*365/'Revenue Model'!E7 -> 6.1083766 | F30: =F9*365/'Revenue Model'!F7 -> 4.0908731 | G30: =G9*365/'Revenue Model'!G7 -> 1.2628551 | H30: =$G$30 -> 1.2628551 | I30: =$G$30 -> 1.2628551 | J30: =$G$30 -> 1.2628551 | K30: =$G$30 -> 1.2628551 | L30: =$G$30 -> 1.2628551
A31: Other current assets | C31: =C10*365/'Revenue Model'!C7 -> 3.2946356 | D31: =D10*365/'Revenue Model'!D7 -> 3.3776168 | E31: =E10*365/'Revenue Model'!E7 -> 2.8793198 | F31: =F10*365/'Revenue Model'!F7 -> 4.6333221 | G31: =G10*365/'Revenue Model'!G7 -> 4.1242802 | H31: =AVERAGE($E$31:$G$31) -> 3.878974 | I31: =AVERAGE($E$31:$G$31) -> 3.878974 | J31: =AVERAGE($E$31:$G$31) -> 3.878974 | K31: =AVERAGE($E$31:$G$31) -> 3.878974 | L31: =AVERAGE($E$31:$G$31) -> 3.878974
A32: Income tax assets (current) | C32: =C11*365/'Revenue Model'!C7 -> 0 | D32: =D11*365/'Revenue Model'!D7 -> 0 | E32: =E11*365/'Revenue Model'!E7 -> 0 | F32: =F11*365/'Revenue Model'!F7 -> 0 | G32: =G11*365/'Revenue Model'!G7 -> 1.7670517 | H32: =$G$32 -> 1.7670517 | I32: =$G$32 -> 1.7670517 | J32: =$G$32 -> 1.7670517 | K32: =$G$32 -> 1.7670517 | L32: =$G$32 -> 1.7670517
A33: Borrowings (short-term) | C33: =C14*365/'Revenue Model'!C7 -> 3.3619549 | D33: =D14*365/'Revenue Model'!D7 -> 3.9192262 | E33: =E14*365/'Revenue Model'!E7 -> 3.1324597 | F33: =F14*365/'Revenue Model'!F7 -> 3.5103677 | G33: =G14*365/'Revenue Model'!G7 -> 4.0738873 | H33: =$G$33 -> 4.0738873 | I33: =$G$33 -> 4.0738873 | J33: =$G$33 -> 4.0738873 | K33: =$G$33 -> 4.0738873 | L33: =$G$33 -> 4.0738873
A34: Lease liabilities (short-term) | C34: =C15*365/'Revenue Model'!C7 -> 0.34862185 | D34: =D15*365/'Revenue Model'!D7 -> 0.44687404 | E34: =E15*365/'Revenue Model'!E7 -> 0.3700395 | F34: =F15*365/'Revenue Model'!F7 -> 0.42354682 | G34: =G15*365/'Revenue Model'!G7 -> 0.41884085 | H34: =$G$34 -> 0.41884085 | I34: =$G$34 -> 0.41884085 | J34: =$G$34 -> 0.41884085 | K34: =$G$34 -> 0.41884085 | L34: =$G$34 -> 0.41884085
A35: Trade payables | C35: =C16*365/('P&L'!C10+'P&L'!C11+'P&L'!C12) -> 88.367373 | D35: =D16*365/('P&L'!D10+'P&L'!D11+'P&L'!D12) -> 75.774406 | E35: =E16*365/('P&L'!E10+'P&L'!E11+'P&L'!E12) -> 72.563019 | F35: =F16*365/('P&L'!F10+'P&L'!F11+'P&L'!F12) -> 80.454863 | G35: =G16*365/('P&L'!G10+'P&L'!G11+'P&L'!G12) -> 77.306816 | H35: =AVERAGE($E$35:$G$35) -> 76.774899 | I35: =AVERAGE($E$35:$G$35) -> 76.774899 | J35: =AVERAGE($E$35:$G$35) -> 76.774899 | K35: =AVERAGE($E$35:$G$35) -> 76.774899 | L35: =AVERAGE($E$35:$G$35) -> 76.774899 | M35: Trade payable days based on materials + stock-in-trade purchases + change in inventories.
A36: Other financial liabilities (current) | C36: =C17*365/'Revenue Model'!C7 -> 2.1128347 | D36: =D17*365/'Revenue Model'!D7 -> 1.7981184 | E36: =E17*365/'Revenue Model'!E7 -> 1.8157902 | F36: =F17*365/'Revenue Model'!F7 -> 2.4620772 | G36: =G17*365/'Revenue Model'!G7 -> 2.5235696 | H36: =$G$36 -> 2.5235696 | I36: =$G$36 -> 2.5235696 | J36: =$G$36 -> 2.5235696 | K36: =$G$36 -> 2.5235696 | L36: =$G$36 -> 2.5235696
A37: Other current liabilities | C37: =C18*365/'Revenue Model'!C7 -> 6.727093 | D37: =D18*365/'Revenue Model'!D7 -> 6.1302522 | E37: =E18*365/'Revenue Model'!E7 -> 6.0062231 | F37: =F18*365/'Revenue Model'!F7 -> 5.8325827 | G37: =G18*365/'Revenue Model'!G7 -> 6.8513836 | H37: =AVERAGE($E$37:$G$37) -> 6.2300631 | I37: =AVERAGE($E$37:$G$37) -> 6.2300631 | J37: =AVERAGE($E$37:$G$37) -> 6.2300631 | K37: =AVERAGE($E$37:$G$37) -> 6.2300631 | L37: =AVERAGE($E$37:$G$37) -> 6.2300631
A38: Provisions (current) | C38: =C19*365/'Revenue Model'!C7 -> 2.0728675 | D38: =D19*365/'Revenue Model'!D7 -> 2.2127553 | E38: =E19*365/'Revenue Model'!E7 -> 2.0588857 | F38: =F19*365/'Revenue Model'!F7 -> 1.5400298 | G38: =G19*365/'Revenue Model'!G7 -> 1.9754911 | H38: =AVERAGE($E$38:$G$38) -> 1.8581355 | I38: =AVERAGE($E$38:$G$38) -> 1.8581355 | J38: =AVERAGE($E$38:$G$38) -> 1.8581355 | K38: =AVERAGE($E$38:$G$38) -> 1.8581355 | L38: =AVERAGE($E$38:$G$38) -> 1.8581355
A41: Debt Schedule | C41: FY21 | D41: FY22 | E41: FY23 | F41: FY24 | G41: FY25 | H41: FY26E | I41: FY27E | J41: FY28E | K41: FY29E | L41: FY30E
A42: Long-term borrowings | C42: ='Balance Sheet'!C40 -> 45.18 | D42: ='Balance Sheet'!D40 -> 36.17 | E42: ='Balance Sheet'!E40 -> 20.09 | F42: 20.88 | G42: 11.6 | H42: =G42+H54 -> 12.18 | I42: =H42+I54 -> 12.789 | J42: =I42+J54 -> 13.42845 | K42: =J42+K54 -> 14.099873 | L42: =K42+L54 -> 14.804866
A43: Short-term borrowings | C43: ='Balance Sheet'!C48 -> 285.16 | D43: ='Balance Sheet'!D48 -> 317.31 | E43: ='Balance Sheet'!E48 -> 293.15 | F43: ='Balance Sheet'!F48 -> 363.43 | G43: ='Balance Sheet'!G48 -> 456.76 | H43: =H14 -> 456.76 | I43: =I14 -> 456.76 | J43: =J14 -> 456.76 | K43: =K14 -> 456.76 | L43: =L14 -> 456.76
...

Sheet P&L
A1: Hero MotoCorp | Profit & Loss Statement
A2: All figures in Rs Crore
A3: P&L Statement | C3: FY21 | D3: FY22 | E3: FY23 | F3: FY24 | G3: FY25 | H3: FY26E | I3: FY27E | J3: FY28E | K3: FY29E | L3: FY30E
A4: Income
A5: Revenue from operations | C5: 30959.19 | D5: 29551.28 | E5: 34158.38 | F5: 37788.62 | G5: 40923.42 | H5: ='Revenue Model'!H7 -> 50467.594 | I5: ='Revenue Model'!I7 -> 61362.657 | J5: ='Revenue Model'!J7 -> 74217.347 | K5: ='Revenue Model'!K7 -> 91045.505 | L5: ='Revenue Model'!L7 -> 111499.81 | M5: Linked directly to Revenue Model revenue from operations.
A6: Other income | C6: 557.9 | D6: 555.01 | E6: 569.01 | F6: 854.54 | G6: 1044.08 | H6: ='Revenue Model'!H8 -> 1089.8426 | I6: ='Revenue Model'!I8 -> 1325.1204 | J6: ='Revenue Model'!J8 -> 1602.7161 | K6: ='Revenue Model'!K8 -> 1966.1185 | L6: ='Revenue Model'!L8 -> 2407.827 | M6: Linked directly to Revenue Model other income.
A7: Total income | C7: =C5+C6 -> 31517.09 | D7: =D5+D6 -> 30106.29 | E7: =E5+E6 -> 34727.39 | F7: =F5+F6 -> 38643.16 | G7: =G5+G6 -> 41967.5 | H7: =H5+H6 -> 51557.436 | I7: =I5+I6 -> 62687.777 | J7: =J5+J6 -> 75820.063 | ... L7: =L5+L6 -> 113907.63
A9: Expense
A10: Cost of materials consumed | C10: 21968.04 | D10: 20845.74 | E10: 24060.29 | F10: 24836.89 | G10: 26607.07 | H10: =Assumptions!H4*'Revenue Model'!H7 -> 33843.572 | I10: =Assumptions!I4*'Revenue Model'!I7 -> 41149.802 | J10: =Assumptions!J4*'Revenue Model'!J7 -> 49770.158 | K10: =Assumptions!K4*'Revenue Model'!K7 -> 61055.122 | L10: =Assumptions!L4*'Revenue Model'!L7 -> 74771.777
A11: Purchase of stock-in-trade | C11: 31.14 | D11: 45.95 | E11: 47.43 | F11: 484.2 | G11: 547.91 | H11: =Assumptions!H5*'Revenue Model'!H7 -> 464.14338 | I11: =Assumptions!I5*'Revenue Model'!I7 -> 564.34375 | J11: =Assumptions!J5*'Revenue Model'!J7 -> 682.56653 | K11: =Assumptions!K5*'Revenue Model'!K7 -> 837.33274 | L11: =Assumptions!L5*'Revenue Model'!L7 -> 1025.4481
A12: Change in inventories | C12: -255.57 | D12: 28.67 | E12: -163.69 | F12: 188.35 | G12: -244.34 | H12: =Assumptions!H6*'Revenue Model'!H7 -> -97.208131 | I12: =Assumptions!I6*'Revenue Model'!I7 -> -118.19365 | J12: =Assumptions!J6*'Revenue Model'!J7 -> -142.95371 | K12: =Assumptions!K6*'Revenue Model'!K7 -> -175.36725 | L12: =Assumptions!L6*'Revenue Model'!L7 -> -214.7653
A13: Excise duty | C13: 0 | D13: 0 | E13: 0 | F13: 0 | G13: 0 | H13: =0 -> 0 | I13: =0 -> 0 | J13: =0 -> 0 | K13: =0 -> 0 | L13: =0 -> 0
A14: Employee benefits expense | C14: 1951.02 | D14: 1995.78 | E14: 2250.05 | F14: 2471.55 | G14: 2680.07 | H14: =Assumptions!H7*'Revenue Model'!H7 -> 3310.0953 | I14: =Assumptions!I7*'Revenue Model'!I7 -> 4024.6865 | J14: =Assumptions!J7*'Revenue Model'!J7 -> 4867.8067 | K14: =Assumptions!K7*'Revenue Model'!K7 -> 5971.5409 | L14: =Assumptions!L7*'Revenue Model'!L7 -> 7313.1084
A15: Finance costs | C15: 46.41 | D15: 53.1 | E15: 104.88 | F15: 76.37 | G15: 70.65 | H15: =Schedules!H50 -> 83.632801 | I15: =Schedules!I50 -> 80.821636 | J15: =Schedules!J50 -> 84.12232 | K15: =Schedules!K50 -> 84.414312 | L15: =Schedules!L50 -> 86.332716
A16: Depreciation & amortisation | C16: 715.12 | D16: 689.52 | E16: 697.39 | F16: 757.36 | G16: 824.59 | H16: =Schedules!H77 -> 859.64898 | I16: =Schedules!I77 -> 931.98421 | J16: =Schedules!J77 -> 1015.0359 | K16: =Schedules!K77 -> 1093.7633 | L16: =Schedules!L77 -> 1185.2459
A17: Other expenses | C17: 3165.05 | D17: 3190.37 | E17: 3870.53 | F17: 4458 | G17: 5386.87 | H17: =Assumptions!H8*'Revenue Model'!H7 -> 6105.17 | I17: =Assumptions!I8*'Revenue Model'!I7 -> 7423.1684 | J17: =Assumptions!J8*'Revenue Model'!J7 -> 8978.227 | K17: =Assumptions!K8*'Revenue Model'!K7 -> 11013.964 | L17: =Assumptions!L8*'Revenue Model'!L7 -> 13488.364
A18: Total expense | C18: =SUM(C10:C17) -> 27621.21 | D18: =SUM(D10:D17) -> 26849.13 | E18: =SUM(E10:E17) -> 30866.88 | F18: =SUM(F10:F17) -> 33272.72 | G18: =SUM(G10:G17) -> 35872.82 | H18: =SUM(H10:H17) -> 44569.054 | I18: =SUM(I10:I17) -> 54056.613 | J18: =SUM(J10:J17) -> 65254.963 | ... L18: =SUM(L10:L17) -> 97655.511
A20: Profit before associates, exceptional & tax | C20: =C7-C18 -> 3895.88 | D20: =D7-D18 -> 3257.16 | E20: =E7-E18 -> 3860.51 | F20: =F7-F18 -> 5370.44 | G20: =G7-G18 -> 6094.68 | H20: =H7-H18 -> 6988.3821 | I20: =I7-I18 -> 8631.1643 | J20: =J7-J18 -> 10565.1 | ... L20: =L7-L18 -> 16252.121
A21: Share of profit/(loss) of associates | C21: -46.56 | D21: -199.05 | E21: 3.11 | F21: -120.25 | G21: -161.12 | H21: =Assumptions!H10 -> -92.753333 | I21: =Assumptions!I10 -> -92.753333 | J21: =Assumptions!J10 -> -92.753333 | K21: =Assumptions!K10 -> -92.753333 | L21: =Assumptions!L10 -> -92.753333
A22: Profit before exceptional items & tax | C22: =C20+C21 -> 3849.32 | D22: =D20+D21 -> 3058.11 | E22: =E20+E21 -> 3863.62 | F22: =F20+F21 -> 5250.19 | G22: =G20+G21 -> 5933.56 | H22: =H20+H21 -> 6895.6288 | I22: =I20+I21 -> 8538.4109 | J22: =J20+J21 -> 10472.347 | ... L22: =L20+L21 -> 16159.368
A23: Exceptional items | C23: 0 | D23: 0 | E23: 0 | F23: -159.99 | G23: 0 | H23: =0 -> 0 | I23: =0 -> 0 | J23: =0 -> 0 | K23: =0 -> 0 | L23: =0 -> 0
A24: Profit before tax | C24: =C22+C23 -> 3849.32 | D24: =D22+D23 -> 3058.11 | E24: =E22+E23 -> 3863.62 | F24: =F22+F23 -> 5090.2 | G24: =G22+G23 -> 5933.56 | H24: =H22+H23 -> 6895.6288 | I24: =I22+I23 -> 8538.4109 | J24: =J22+J23 -> 10472.347 | ... L24: =L22+L23 -> 16159.368
A26: Tax expense
A27: Current tax | C27: 931.38 | D27: 805.44 | E27: 947.69 | F27: 1264.18 | G27: 1448.02
A28: Adjustment of earlier periods | C28: 0 | D28: 0 | E28: 0 | F28: 0 | G28: 0
A29: Deferred tax charge/(credit) | C29: -18.11 | D29: -76.38 | E29: 116.03 | F29: 83.86 | G29: 109.73
A30: Net tax expense | C30: =SUM(C27:C29) -> 913.27 | D30: =SUM(D27:D29) -> 729.06 | E30: =SUM(E27:E29) -> 1063.72 | F30: =SUM(F27:F29) -> 1348.04 | G30: =SUM(G27:G29) -> 1557.75 | H30: =Assumptions!H11*H24 -> 1844.9933 | I30: =Assumptions!I11*I24 -> 2284.5358 | J30: =Assumptions!J11*J24 -> 2801.9793 | K30: =Assumptions!K11*K24 -> 3488.4717 | L30: =Assumptions!L11*L24 -> 4323.5978
A31: Profit for the year | C31: =C24-C30 -> 2936.05 | D31: =D24-D30 -> 2329.05 | E31: =E24-E30 -> 2799.9 | F31: =F24-F30 -> 3742.16 | G31: =G24-G30 -> 4375.81 | H31: =H24-H30 -> 5050.6355 | I31: =I24-I30 -> 6253.8752 | J31: =J24-J30 -> 7670.3673 | ... L31: =L24-L30 -> 11835.77
A33: Memo:
A34: Operating EBIT (for DCF) | C34: =C5-SUM(C10:C14,C16:C17) -> 3384.39 | D34: =D5-SUM(D10:D14,D16:D17) -> 2755.25 | E34: =E5-SUM(E10:E14,E16:E17) -> 3396.38 | F34: =F5-SUM(F10:F14,F16:F17) -> 4592.27 | G34: =G5-SUM(G10:G14,G16:G17) -> 5121.25 | H34: =H5-SUM(H10:H14,H16:H17) -> 5982.1723 | I34: =I5-SUM(I10:I14,I16:I17) -> 7386.8655 | J34: =J5-SUM(J10:J14,J16:J17) -> 9046.5062 | ... L34: =L5-SUM(L10:L14,L16:L17) -> 13930.627 | M34: Revenue less operating costs and D&A; excludes other income, associate income and finance costs.
A35: Effective tax rate (%) | C35: =C30/C24 -> 0.23725489 | D35: =D30/D24 -> 0.23840215 | E35: =E30/E24 -> 0.27531693 | F35: =F30/F24 -> 0.26483046 | G35: =G30/G24 -> 0.26253211 | H35: =H30/H24 -> 0.26755983 | I35: =I30/I24 -> 0.26755983 | J35: =J30/J24 -> 0.26755983 | ... L35: =L30/L24 -> 0.26755983
A36: Net profit margin (%) | C36: =C31/C5 -> 0.094836138 | D36: =D31/D5 -> 0.078813845 | E36: =E31/E5 -> 0.081968173 | F36: =F31/F5 -> 0.099028755 | G36: =G31/G5 -> 0.10692679 | H36: =H31/H5 -> 0.1000768 | I36: =I31/I5 -> 0.10191663 | J36: =J31/J5 -> 0.10335006 | ... L36: =L31/L5 -> 0.10615059
A37: Operating EBIT margin (%) | C37: =C34/C5 -> 0.10931778 | D37: =D34/D5 -> 0.093236232 | E37: =E34/E5 -> 0.099430359 | F37: =F34/F5 -> 0.12152521 | G37: =G34/G5 -> 0.12514228 | H37: =H34/H5 -> 0.11853492 | I37: =I34/I5 -> 0.12038047 | J37: =J34/J5 -> 0.12189207 | ... L37: =L34/L5 -> 0.12493858 | M37: Operating EBIT / Revenue; consistent with the EBIT used in FCFF.

Sheet Balance Sheet
A1: Hero MotoCorp | Balance Sheet
A2: All figures are in crore
A3: ASSETS | C3: FY21 | D3: FY22 | E3: FY23 | F3: FY24 | G3: FY25 | H3: FY26E | I3: FY27E | J3: FY28E | K3: FY29E | L3: FY30E
A4: Non-current assets
A5: (a) Property, plant & equipment | C5: 5550.67 | D5: 5354.34 | E5: 5159.42 | F5: 5212.58 | G5: 5219.13 | H5: =Schedules!H63 -> 5417.3231 | I5: =Schedules!I63 -> 5576.4959 | J5: =Schedules!J63 -> 5758.9695 | K5: =Schedules!K63 -> 5964.2026 | L5: =Schedules!L63 -> 6175.9702
A6: (b) Capital work-in-progress | C6: 236.4 | D6: 149.13 | E6: 122.09 | F6: 127.16 | G6: 105.37 | H6: =$G$6 -> 105.37 | I6: =$G$6 -> 105.37 | J6: =$G$6 -> 105.37 | K6: =$G$6 -> 105.37 | L6: =$G$6 -> 105.37
A7: (c) Right-of-use assets | C7: 511.24 | D7: 517.9 | E7: 481.28 | F7: 475.97 | G7: 483.39 | H7: =Schedules!H69 -> 495.05452 | I7: =Schedules!I69 -> 515.80633 | J7: =Schedules!J69 -> 524.92937 | K7: =Schedules!K69 -> 540.97151 | L7: =Schedules!L69 -> 560.7749
A8: (d) Other intangible assets | C8: 318.48 | D8: 321.3 | E8: 518.5 | F8: 543.65 | G8: 580.46 | H8: =Schedules!H66 -> 582.92036 | I8: =Schedules!I66 -> 588.5552 | J8: =Schedules!J66 -> 593.50215 | K8: =Schedules!K66 -> 598.01032 | L8: =Schedules!L66 -> 603.08571
A9: (e) Intangible assets under development | C9: 258.73 | D9: 368.09 | E9: 331.62 | F9: 356.9 | G9: 381.81 | H9: =$G$9 -> 381.81 | I9: =$G$9 -> 381.81 | J9: =$G$9 -> 381.81 | K9: =$G$9 -> 381.81 | L9: =$G$9 -> 381.81
A10: (f) Investments in associates | C10: 2407.69 | D10: 2202.51 | E10: 2618.7 | F10: 3083.59 | G10: 2980.94 | H10: =G10+'P&L'!H21 -> 2888.1867 | I10: =H10+'P&L'!I21 -> 2795.4333 | J10: =I10+'P&L'!J21 -> 2702.68 | K10: =J10+'P&L'!K21 -> 2609.9267 | L10: =K10+'P&L'!L21 -> 2517.1733
A11: Financial assets
A12: (i) Investments | C12: 1948.59 | D12: 2455.05 | E12: 4600.38 | F12: 5362.57 | G12: 4767.33 | H12: =$G$12 -> 4767.33 | I12: =$G$12 -> 4767.33 | J12: =$G$12 -> 4767.33 | K12: =$G$12 -> 4767.33 | L12: =$G$12 -> 4767.33
A13: (ii) Loans | C13: 52.64 | D13: 17.43 | E13: 19.87 | F13: 21.15 | G13: 24.87 | H13: =$G$13 -> 24.87 | I13: =$G$13 -> 24.87 | J13: =$G$13 -> 24.87 | K13: =$G$13 -> 24.87 | L13: =$G$13 -> 24.87
A14: (iii) Other financial assets | C14: 0 | D14: 42.01 | E14: 206.09 | F14: 189.44 | G14: 47.09 | H14: =$G$14 -> 47.09 | I14: =$G$14 -> 47.09 | J14: =$G$14 -> 47.09 | K14: =$G$14 -> 47.09 | L14: =$G$14 -> 47.09
A15: (h) Income tax assets (net) | C15: 378.49 | D15: 358.07 | E15: 270.69 | F15: 335.68 | G15: 254.49 | H15: =$G$15 -> 254.49 | I15: =$G$15 -> 254.49 | J15: =$G$15 -> 254.49 | K15: =$G$15 -> 254.49 | L15: =$G$15 -> 254.49
A16: (i) Other non-current assets | C16: 62.68 | D16: 120.34 | E16: 153.06 | F16: 128.65 | G16: 111.55 | H16: =$G$16 -> 111.55 | I16: =$G$16 -> 111.55 | J16: =$G$16 -> 111.55 | K16: =$G$16 -> 111.55 | L16: =$G$16 -> 111.55
A17: Total non-current assets | C17: =SUM(C5:C16) -> 11725.61 | D17: =SUM(D5:D16) -> 11906.17 | E17: =SUM(E5:E16) -> 14481.7 | F17: =SUM(F5:F16) -> 15837.34 | G17: =SUM(G5:G16) -> 14956.43 | H17: =SUM(H5:H16) -> 15075.995 | I17: =SUM(I5:I16) -> 15168.801 | J17: =SUM(J5:J16) -> 15272.591 | ... L17: =SUM(L5:L16) -> 15549.514
A18: Current assets
A19: (a) Inventories | C19: 1789.27 | D19: 1472.41 | E19: 1756.39 | F19: 1755.9 | G19: 2013.34 | H19: =Schedules!H4 -> 2474.3104 | I19: =Schedules!I4 -> 3008.4704 | J19: =Schedules!J4 -> 3638.7064 | K19: =Schedules!K4 -> 4463.7524 | L19: =Schedules!L4 -> 5466.5799
A20: Financial assets
A21: (i) Investments | C21: 6225.34 | D21: 5870.31 | E21: 3671.85 | F21: 4305.08 | G21: 6635.99 | H21: =Schedules!H5 -> 6635.99 | I21: =Schedules!I5 -> 6635.99 | J21: =Schedules!J5 -> 6635.99 | K21: =Schedules!K5 -> 6635.99 | L21: =Schedules!L5 -> 6635.99
A22: (ii) Trade receivables | C22: 2274.68 | D22: 2158.49 | E22: 2719.47 | F22: 2630.22 | G22: 3381.29 | H22: =Schedules!H6 -> 3900.167 | I22: =Schedules!I6 -> 4742.1442 | J22: =Schedules!J6 -> 5735.5626 | K22: =Schedules!K6 -> 7036.0531 | L22: =Schedules!L6 -> 8616.7742
A23: (iii) Cash & cash equivalents | C23: 274.62 | D23: 181.02 | E23: 226.3 | F23: 604.91 | G23: 383.55 | H23: =CFS!H20 -> 5896.1654 | I23: =CFS!I20 -> 12371.121 | J23: =CFS!J20 -> 20306.625 | K23: =CFS!K20 -> 30203.219 | L23: =CFS!L20 -> 42476.532
A24: (iv) Bank balances (other) | C24: 121.62 | D24: 118.72 | E24: 196.5 | F24: 91.56 | G24: 190.53 | H24: =Schedules!H7 -> 190.53 | I24: =Schedules!I7 -> 190.53 | J24: =Schedules!J7 -> 190.53 | K24: =Schedules!K7 -> 190.53 | L24: =Schedules!L7 -> 190.53
A25: (v) Loans | C25: 39.77 | D25: 22.81 | E25: 23.71 | F25: 24.56 | G25: 27.07 | H25: =Schedules!H8 -> 27.07 | I25: =Schedules!I8 -> 27.07 | J25: =Schedules!J8 -> 27.07 | K25: =Schedules!K8 -> 27.07 | L25: =Schedules!L8 -> 27.07
A26: (vi) Other financial assets | C26: 365.73 | D26: 475 | E26: 571.65 | F26: 423.53 | G26: 141.59 | H26: =Schedules!H9 -> 141.59 | I26: =Schedules!I9 -> 141.59 | J26: =Schedules!J9 -> 141.59 | K26: =Schedules!K9 -> 141.59 | L26: =Schedules!L9 -> 141.59
A27: (c) Other current assets | C27: 279.45 | D27: 273.46 | E27: 269.46 | F27: 479.69 | G27: 462.41 | H27: =Schedules!H10 -> 536.33558 | I27: =Schedules!I10 -> 652.12097 | J27: =Schedules!J10 -> 788.73195 | K27: =Schedules!K10 -> 967.57027 | L27: =Schedules!L10 -> 1184.9448
A28: (d) Income tax assets (net) | C28: 0 | D28: 0 | E28: 0 | F28: 0 | G28: 198.12 | H28: =Schedules!H11 -> 198.12 | I28: =Schedules!I11 -> 198.12 | J28: =Schedules!J11 -> 198.12 | K28: =Schedules!K11 -> 198.12 | L28: =Schedules!L11 -> 198.12
A29: Total current assets | C29: =SUM(C19:C28) -> 11370.48 | D29: =SUM(D19:D28) -> 10572.22 | E29: =SUM(E19:E28) -> 9435.33 | F29: =SUM(F19:F28) -> 10315.45 | G29: =SUM(G19:G28) -> 13433.89 | H29: =SUM(H19:H28) -> 20000.278 | I29: =SUM(I19:I28) -> 27967.157 | J29: =SUM(J19:J28) -> 37662.926 | ... L29: =SUM(L19:L28) -> 64938.13
A30: Total assets | C30: =C17+C29 -> 23096.09 | D30: =D17+D29 -> 22478.39 | E30: =E17+E29 -> 23917.03 | F30: =F17+F29 -> 26152.79 | G30: =G17+G29 -> 28390.32 | H30: =H17+H29 -> 35076.273 | I30: =I17+I29 -> 43135.957 | J30: =J17+J29 -> 52935.517 | ... L30: =L17+L29 -> 80487.645
A31: EQUITY & LIABILITIES | C31: FY21 | D31: FY22 | E31: FY23 | F31: FY24 | G31: FY25 | H31: FY26E | I31: FY27E | J31: FY28E | K31: FY29E | L31: FY30E
A32: Equity
A33: (a) Equity share capital | C33: 39.96 | D33: 39.96 | E33: 39.97 | F33: 39.98 | G33: 40 | H33: =G33 -> 40 | I33: =H33 -> 40 | J33: =I33 -> 40 | K33: =J33 -> 40 | L33: =K33 -> 40
A34: (b) Other equity | C34: 15376.46 | D34: 15806.69 | E34: 16615.6 | F34: 17658.94 | G34: 19232.04 | H34: =G34-11.6+'P&L'!H31 -> 24271.075 | I34: =H34+'P&L'!I31 -> 30524.951 | J34: =I34+'P&L'!J31 -> 38195.318 | K34: =J34+'P&L'!K31 -> 47744.946 | L34: =K34+'P&L'!L31 -> 59580.716 | M34: FY26E includes a one-time Rs 11.60 Cr opening normalization to reconcile the FY25 source-model balance-sheet mismatch; subsequent years roll forward normally.
A35: Equity attributable to owners | C35: =C33+C34 -> 15416.42 | D35: =D33+D34 -> 15846.65 | E35: =E33+E34 -> 16655.57 | F35: =F33+F34 -> 17698.92 | G35: =G33+G34 -> 19272.04 | H35: =H33+H34 -> 24311.075 | I35: =I33+I34 -> 30564.951 | J35: =J33+J34 -> 38235.318 | ... L35: =L33+L34 -> 59620.716
A36: Non-controlling interests | C36: 143.19 | D36: 148.05 | E36: 125.06 | F36: 135.65 | G36: 132.05 | H36: =G36 -> 132.05 | I36: =H36 -> 132.05 | J36: =I36 -> 132.05 | K36: =J36 -> 132.05 | L36: =K36 -> 132.05
A37: Total equity | C37: =C35+C36 -> 15559.61 | D37: =D35+D36 -> 15994.7 | E37: =E35+E36 -> 16780.63 | F37: =F35+F36 -> 17834.57 | G37: =G35+G36 -> 19404.09 | H37: =H35+H36 -> 24443.125 | I37: =I35+I36 -> 30697.001 | J37: =J35+J36 -> 38367.368 | ... L37: =L35+L36 -> 59752.766
A38: Non-current liabilities
A39: Financial liabilities
A40: (i) Borrowings | C40: 45.18 | D40: 36.17 | E40: 20.09 | F40: 20.9 | G40: 11.6 | H40: =Schedules!H42 -> 12.18 | I40: =Schedules!I42 -> 12.789 | J40: =Schedules!J42 -> 13.42845 | K40: =Schedules!K42 -> 14.099873 | L40: =Schedules!L42 -> 14.804866
...

Sheet CFS
A1: Hero MotoCorp | Cash Flow Statement (forecast)
A2: All figures in Rs Crore. Integrated cash flow; closing cash reconciles to the Balance Sheet.
A3: Cash Flow Statement | H3: FY26E | I3: FY27E | J3: FY28E | K3: FY29E | L3: FY30E
A4: Net profit | H4: ='P&L'!H31 -> 5050.6355 | I4: ='P&L'!I31 -> 6253.8752 | J4: ='P&L'!J31 -> 7670.3673 | K4: ='P&L'!K31 -> 9549.6278 | L4: ='P&L'!L31 -> 11835.77
A5: Add: Finance costs | H5: ='P&L'!H15 -> 83.632801 | I5: ='P&L'!I15 -> 80.821636 | J5: ='P&L'!J15 -> 84.12232 | K5: ='P&L'!K15 -> 84.414312 | L5: ='P&L'!L15 -> 86.332716
A6: Add: Depreciation & amortisation | H6: ='P&L'!H16 -> 859.64898 | I6: ='P&L'!I16 -> 931.98421 | J6: ='P&L'!J16 -> 1015.0359 | K6: ='P&L'!K16 -> 1093.7633 | L6: ='P&L'!L16 -> 1185.2459
A7: Less: Change in net working capital | H7: =-Schedules!H22 -> 571.15406 | I7: =-Schedules!I22 -> 302.97665 | J7: =-Schedules!J22 -> 357.47117 | K7: =-Schedules!K22 -> 467.96782 | L7: =-Schedules!L22 -> 568.80584
A8: Cash flow from operating activities | H8: =SUM(H4:H7)-'P&L'!H21 -> 6657.8247 | I8: =SUM(I4:I7)-'P&L'!I21 -> 7662.411 | J8: =SUM(J4:J7)-'P&L'!J21 -> 9219.7501 | K8: =SUM(K4:K7)-'P&L'!K21 -> 11288.527 | L8: =SUM(L4:L7)-'P&L'!L21 -> 13768.908
A10: Change in non-operating assets (net of associate non-cash profit) | H10: =-(('Balance Sheet'!H6-'Balance Sheet'!G6)+('Balance Sheet'!H9-'Balance Sheet'!G9)+('Balance Sheet'!H10-'Balance Sheet'!G10)+('Balance Sheet'!H12-'Balance Sheet'!G12)+('Balance Sheet'!H13-'Balance Sheet'!G13)+('Balance Sheet'!H14-'Balance Sheet'!G14)+('Balance Sheet'!H16-'Balance Sheet'!G16)-('P&L'!H21)) -> 0 | I10: =-(('Balance Sheet'!I6-'Balance Sheet'!H6)+('Balance Sheet'!I9-'Balance Sheet'!H9)+('Balance Sheet'!I10-'Balance Sheet'!H10)+('Balance Sheet'!I12-'Balance Sheet'!H12)+('Balance Sheet'!I13-'Balance Sheet'!H13)+('Balance Sheet'!I14-'Balance Sheet'!H14)+('Balance Sheet'!I16-'Balance Sheet'!H16)-('P&L'!I21)) -> 0 | J10: =-(('Balance Sheet'!J6-'Balance Sheet'!I6)+('Balance Sheet'!J9-'Balance Sheet'!I9)+('Balance Sheet'!J10-'Balance Sheet'!I10)+('Balance Sheet'!J12-'Balance Sheet'!I12)+('Balance Sheet'!J13-'Balance Sheet'!I13)+('Balance Sheet'!J14-'Balance Sheet'!I14)+('Balance Sheet'!J16-'Balance Sheet'!I16)-('P&L'!J21)) -> 0 | K10: =-(('Balance Sheet'!K6-'Balance Sheet'!J6)+('Balance Sheet'!K9-'Balance Sheet'!J9)+('Balance Sheet'!K10-'Balance Sheet'!J10)+('Balance Sheet'!K12-'Balance Sheet'!J12)+('Balance Sheet'!K13-'Balance Sheet'!J13)+('Balance Sheet'!K14-'Balance Sheet'!J14)+('Balance Sheet'!K16-'Balance Sheet'!J16)-('P&L'!K21)) -> 0 | L10: =-(('Balance Sheet'!L6-'Balance Sheet'!K6)+('Balance Sheet'!L9-'Balance Sheet'!K9)+('Balance Sheet'!L10-'Balance Sheet'!K10)+('Balance Sheet'!L12-'Balance Sheet'!K12)+('Balance Sheet'!L13-'Balance Sheet'!K13)+('Balance Sheet'!L14-'Balance Sheet'!K14)+('Balance Sheet'!L16-'Balance Sheet'!K16)-('P&L'!L21)) -> 0
A11: Less: Capital expenditure | H11: =-Schedules!H88 -> -1071.967 | I11: =-Schedules!I88 -> -1117.5437 | J11: =-Schedules!J88 -> -1211.5795 | K11: =-Schedules!K88 -> -1319.5467 | L11: =-Schedules!L88 -> -1421.8923
A12: Cash flow from investing activities | H12: =H10+H11 -> -1071.967 | I12: =I10+I11 -> -1117.5437 | J12: =J10+J11 -> -1211.5795 | K12: =K10+K11 -> -1319.5467 | L12: =L10+L11 -> -1421.8923
A14: Change in equity (share capital) | H14: ='Balance Sheet'!H33-'Balance Sheet'!G33 -> 0 | I14: ='Balance Sheet'!I33-'Balance Sheet'!H33 -> 0 | J14: ='Balance Sheet'!J33-'Balance Sheet'!I33 -> 0 | K14: ='Balance Sheet'!K33-'Balance Sheet'!J33 -> 0 | L14: ='Balance Sheet'!L33-'Balance Sheet'!K33 -> 0
A15: Net loans raised (long-term) | H15: =('Balance Sheet'!H40-'Balance Sheet'!G40)+('Balance Sheet'!H48-'Balance Sheet'!G48)+('Balance Sheet'!H41-'Balance Sheet'!G41)+('Balance Sheet'!H49-'Balance Sheet'!G49) -> 10.3905 | I15: =('Balance Sheet'!I40-'Balance Sheet'!H40)+('Balance Sheet'!I48-'Balance Sheet'!H48)+('Balance Sheet'!I41-'Balance Sheet'!H41)+('Balance Sheet'!I49-'Balance Sheet'!H49) -> 10.910025 | J15: =('Balance Sheet'!J40-'Balance Sheet'!I40)+('Balance Sheet'!J48-'Balance Sheet'!I48)+('Balance Sheet'!J41-'Balance Sheet'!I41)+('Balance Sheet'!J49-'Balance Sheet'!I49) -> 11.455526 | K15: =('Balance Sheet'!K40-'Balance Sheet'!J40)+('Balance Sheet'!K48-'Balance Sheet'!J48)+('Balance Sheet'!K41-'Balance Sheet'!J41)+('Balance Sheet'!K49-'Balance Sheet'!J49) -> 12.028303 | L15: =('Balance Sheet'!L40-'Balance Sheet'!K40)+('Balance Sheet'!L48-'Balance Sheet'!K48)+('Balance Sheet'!L41-'Balance Sheet'!K41)+('Balance Sheet'!L49-'Balance Sheet'!K49) -> 12.629718
A16: Finance costs paid | H16: =-'P&L'!H15 -> -83.632801 | I16: =-'P&L'!I15 -> -80.821636 | J16: =-'P&L'!J15 -> -84.12232 | K16: =-'P&L'!K15 -> -84.414312 | L16: =-'P&L'!L15 -> -86.332716
A17: Dividend paid | H17: =0 -> 0 | I17: =0 -> 0 | J17: =0 -> 0 | K17: =0 -> 0 | L17: =0 -> 0
A18: Cash flow from financing activities | H18: =SUM(H14:H17) -> -73.242301 | I18: =SUM(I14:I17) -> -69.911611 | J18: =SUM(J14:J17) -> -72.666794 | K18: =SUM(K14:K17) -> -72.38601 | L18: =SUM(L14:L17) -> -73.702999
A20: Closing cash & cash equivalents (to Balance Sheet) | H20: =H8+H12+H18+'Balance Sheet'!G23 -> 5896.1654 | I20: =I8+I12+I18+'Balance Sheet'!H23 -> 12371.121 | J20: =J8+J12+J18+'Balance Sheet'!I23 -> 20306.625 | K20: =K8+K12+K18+'Balance Sheet'!J23 -> 30203.219 | L20: =L8+L12+L18+'Balance Sheet'!K23 -> 42476.532
A22: Net change in cash | H22: =H20-'Balance Sheet'!G23 -> 5512.6154 | I22: =I20-'Balance Sheet'!H23 -> 6474.9557 | J22: =J20-'Balance Sheet'!I23 -> 7935.5038 | K22: =K20-'Balance Sheet'!J23 -> 9896.5938 | L22: =L20-'Balance Sheet'!K23 -> 12273.313
A23: Opening cash | H23: ='Balance Sheet'!G23 -> 383.55 | I23: ='Balance Sheet'!H23 -> 5896.1654 | J23: ='Balance Sheet'!I23 -> 12371.121 | K23: ='Balance Sheet'!J23 -> 20306.625 | L23: ='Balance Sheet'!K23 -> 30203.219
A25: Cash flow reconciliation check | H25: =H20-'Balance Sheet'!H23 -> 0 | I25: =I20-'Balance Sheet'!I23 -> 0 | J25: =J20-'Balance Sheet'!J23 -> 0 | K25: =K20-'Balance Sheet'!K23 -> 0 | L25: =L20-'Balance Sheet'!L23 -> 0

Sheet FCFF
A1: Hero MotoCorp | FCFF & DCF valuation
A2: Free cash flow to firm, discounted at WACC. All figures Rs Crore unless stated.
A3: Rs Crore | C3: FY26E | D3: FY27E | E3: FY28E | F3: FY29E | G3: FY30E
A4: EBIT | C4: ='P&L'!H34 -> 5982.1723 | D4: ='P&L'!I34 -> 7386.8655 | E4: ='P&L'!J34 -> 9046.5062 | F4: ='P&L'!K34 -> 11249.149 | G4: ='P&L'!L34 -> 13930.627
A5: Tax rate | C5: =Assumptions!H11 -> 0.26755983 | D5: =Assumptions!I11 -> 0.26755983 | E5: =Assumptions!J11 -> 0.26755983 | F5: =Assumptions!K11 -> 0.26755983 | G5: =Assumptions!L11 -> 0.26755983
A6: NOPAT = EBIT x (1 - tax) | C6: =C4*(1-C5) -> 4381.5833 | D6: =D4*(1-D5) -> 5410.437 | E6: =E4*(1-E5) -> 6626.0245 | F6: =F4*(1-F5) -> 8239.3284 | G6: =G4*(1-G5) -> 10203.351
A7: Add: Depreciation & amortisation | C7: ='P&L'!H16 -> 859.64898 | D7: ='P&L'!I16 -> 931.98421 | E7: ='P&L'!J16 -> 1015.0359 | F7: ='P&L'!K16 -> 1093.7633 | G7: ='P&L'!L16 -> 1185.2459
A8: Less: Capital expenditure | C8: =-Schedules!H88 -> -1071.967 | D8: =-Schedules!I88 -> -1117.5437 | E8: =-Schedules!J88 -> -1211.5795 | F8: =-Schedules!K88 -> -1319.5467 | G8: =-Schedules!L88 -> -1421.8923
A9: Less: Change in net working capital | C9: =-Schedules!H22 -> 571.15406 | D9: =-Schedules!I22 -> 302.97665 | E9: =-Schedules!J22 -> 357.47117 | F9: =-Schedules!K22 -> 467.96782 | G9: =-Schedules!L22 -> 568.80584
A10: Free cash flow to firm (FCFF) | C10: =SUM(C6:C9) -> 4740.4193 | D10: =SUM(D6:D9) -> 5527.8542 | E10: =SUM(E6:E9) -> 6786.9522 | F10: =SUM(F6:F9) -> 8481.5128 | G10: =SUM(G6:G9) -> 10535.51
A12: Discount period (years) | C12: 1 | D12: 2 | E12: 3 | F12: 4 | G12: 5
A13: Discount factor = 1/(1+WACC)^t | C13: =1/(1+WACC!$C$23)^C12 -> 0.90717596 | D13: =1/(1+WACC!$C$23)^D12 -> 0.82296823 | E13: =1/(1+WACC!$C$23)^E12 -> 0.74657699 | F13: =1/(1+WACC!$C$23)^F12 -> 0.6772767 | G13: =1/(1+WACC!$C$23)^G12 -> 0.61440914
A14: PV of FCFF | C14: =C10*C13 -> 4300.3945 | D14: =D10*D13 -> 4549.2484 | E14: =E10*E13 -> 5066.9823 | F14: =F10*F13 -> 5744.331 | G14: =G10*G13 -> 6473.1139
A16: Sum of PV of FCFF (FY26E-FY30E) | C16: =SUM(C14:G14) -> 26134.07
A17: Terminal growth rate (g) | C17: 0.05 | M17: Terminal growth is an explicit assumption; sensitivity analysis is provided because terminal value represents a large share of enterprise value.
A18: Terminal value at FY30 = FCFF x (1+g)/(WACC-g) | C18: =G10*(1+C17)/(WACC!$C$23-C17) -> 211427.14
A19: PV of terminal value | C19: =C18*G13 -> 129902.77
A20: Enterprise value | C20: =C16+C19 -> 156036.84
A22: Less: Debt + lease (FY25) | C22: =-Schedules!G48 -> -711.53
A23: Add: Cash + bank + current investments (FY25) | C23: ='Balance Sheet'!G23+'Balance Sheet'!G24+'Balance Sheet'!G21 -> 7210.07
A24: Add: Non-current investments + associates (FY25) | C24: ='Balance Sheet'!G12+'Balance Sheet'!G10 -> 7748.27 | M24: Non-current investments and associate carrying values are used as a conservative proxy for non-operating value.
A25: Equity value | C25: =C20+C22+C23+C24 -> 170283.65
A26: Shares outstanding (crore) | C26: =WACC!C17 -> 20
A27: Intrinsic value per share (Rs) | C27: =C25/C26 -> 8514.1823
A29: Memo: current market price (Rs) | C29: =WACC!C16 -> 5000
A30: Implied upside / (downside) | C30: =C27/C29-1 -> 0.70283647

Sheet WACC
A1: Hero MotoCorp | WACC (weighted average cost of capital)
A2: Market inputs are carried from the supplied model; before publication, document the exact source/date for risk-free rate, beta, ERP and market price.
A4: Cost of equity (CAPM)
A5: Risk-free rate (India 10Y G-Sec) | C5: 0.0675
A6: Beta (Hero MotoCorp) | C6: 0.5 | D6: Model input; document the exact source and date before live/publication use.
A7: Equity risk premium (India) | C7: 0.07
A8: Cost of equity = Rf + Beta x ERP | C8: =C5+C6*C7 -> 0.1025
A10: Cost of debt
A11: Pre-tax effective cost of debt + lease obligations (FY25) | C11: =Schedules!G51 -> 0.1055407 | D11: FY25 finance cost / average debt & lease obligations.
A12: Tax rate | C12: =Assumptions!H11 -> 0.26755983
A13: After-tax cost of debt = Kd x (1 - tax) | C13: =C11*(1-C12) -> 0.077302248
A15: Capital structure (market values)
A16: Share price (Rs) | C16: 5000
A17: Shares outstanding (crore) [share capital / Rs 2 face] | C17: ='Balance Sheet'!G33/2 -> 20 | D17: Derived from FY25 reported share capital and Rs 2 face value.
A18: Equity value / market cap (Rs Cr) | C18: =C16*C17 -> 100000
A19: Debt + lease (Rs Cr, FY25) | C19: =Schedules!G48 -> 711.53
A20: Weight of equity | C20: =C18/(C18+C19) -> 0.99293497
A21: Weight of debt | C21: =C19/(C18+C19) -> 0.0070650302
A23: WACC = We x Ke + Wd x Kd(after-tax) | C23: =C20*C8+C21*C13 -> 0.10232198

Sheet Model Checks
A1: Hero MotoCorp | Model Checks
A3: Check | B3: FY26E | C3: FY27E | D3: FY28E | E3: FY29E | F3: FY30E
A4: Revenue model check (Total revenue - revenue) | B4: ='Revenue Model'!H19-'Revenue Model'!H7 -> 0 | C4: ='Revenue Model'!I19-'Revenue Model'!I7 -> 0 | D4: ='Revenue Model'!J19-'Revenue Model'!J7 -> 0 | E4: ='Revenue Model'!K19-'Revenue Model'!K7 -> 0 | F4: ='Revenue Model'!L19-'Revenue Model'!L7 -> 0
A5: Balance sheet check (Assets - Equity & Liabilities) | B5: ='Balance Sheet'!H57 -> 0 | C5: ='Balance Sheet'!I57 -> 0 | D5: ='Balance Sheet'!J57 -> 0 | E5: ='Balance Sheet'!K57 -> 0 | F5: ='Balance Sheet'!L57 -> 0
A6: Cash flow check (CFS closing cash - BS cash) | B6: =CFS!H20-'Balance Sheet'!H23 -> 0 | C6: =CFS!I20-'Balance Sheet'!I23 -> 0 | D6: =CFS!J20-'Balance Sheet'!J23 -> 0 | E6: =CFS!K20-'Balance Sheet'!K23 -> 0 | F6: =CFS!L20-'Balance Sheet'!L23 -> 0
A7: FCFF formula check (FCFF - NOPAT - D&A + Capex + Change NWC) | B7: =FCFF!C10-(FCFF!C6+FCFF!C7+FCFF!C8+FCFF!C9) -> 0 | C7: =FCFF!D10-(FCFF!D6+FCFF!D7+FCFF!D8+FCFF!D9) -> 0 | D7: =FCFF!E10-(FCFF!E6+FCFF!E7+FCFF!E8+FCFF!E9) -> 0 | E7: =FCFF!F10-(FCFF!F6+FCFF!F7+FCFF!F8+FCFF!F9) -> 0 | F7: =FCFF!G10-(FCFF!G6+FCFF!G7+FCFF!G8+FCFF!G9) -> 0
A8: FY25 source balance-sheet discrepancy | B8: ='Balance Sheet'!G57 -> -11.6
A9: Forecast normalization | B9: FY26E onward normalized by Rs 11.60 Cr opening discrepancy; this is a source-data reconciliation, not an operating assumption.
A10: Interpretation | B10: Forecast checks are zero. FY25 remains shown as a source-data discrepancy of Rs 11.60 Cr for transparency.
A11: WACC weights check (We + Wd - 100%) | B11: =WACC!C20+WACC!C21-1 -> 0
A12: Terminal spread check (WACC - g) | B12: =WACC!C23-FCFF!C17 -> 0.052321977
A13: Equity bridge check | B13: =FCFF!C25-(FCFF!C20+FCFF!C22+FCFF!C23+FCFF!C24) -> 0
A14: Shares outstanding check | B14: =FCFF!C26-WACC!C17 -> 0
A15: Additional model integrity checks | B15: Rows 11–14 should be zero except the terminal spread check, which should remain positive; rows 17–18 document historical source/schedule differences.
A17: Historical balance-sheet check (Assets - Equity & Liabilities) | B17: ='Balance Sheet'!C57 -> 0 | C17: ='Balance Sheet'!D57 -> 0 | D17: ='Balance Sheet'!E57 -> 0 | E17: ='Balance Sheet'!F57 -> -20.9 | F17: ='Balance Sheet'!G57 -> -11.6
A18: Historical D&A schedule check (Schedule total - P&L D&A) | B18: =Schedules!C77-'P&L'!C16 -> 0 | C18: =Schedules!D77-'P&L'!D16 -> 25.6 | D18: =Schedules!E77-'P&L'!E16 -> 40 | E18: =Schedules!F77-'P&L'!F16 -> 0 | F18: =Schedules!G77-'P&L'!G16 -> 0
A19: Audit interpretation | B19: Forecast checks are zero. Historical BS residuals exist in FY24 and FY25; historical D&A schedule totals differ from reported P&L D&A in FY22 and FY23.
A20: Valuation interpretation | B20: Terminal value is a large share of enterprise value; WACC, terminal growth, volume and realization assumptions materially drive the DCF output.

Sheet DCF Sensitivity
A1: Hero MotoCorp | DCF Sensitivity Analysis
A2: Intrinsic value per share (Rs) under alternative WACC and terminal growth assumptions.
A4: WACC \ Terminal g | B4: 0.03 | C4: 0.04 | D4: 0.05 | E4: 0.06
A5: 0.09 | B5: =(FCFF!$C$10/(1+$A5)^1+FCFF!$D$10/(1+$A5)^2+FCFF!$E$10/(1+$A5)^3+FCFF!$F$10/(1+$A5)^4+FCFF!$G$10/(1+$A5)^5+(FCFF!$G$10*(1+B$4)/($A5-B$4))/(1+$A5)^5+FCFF!$C$22+FCFF!$C$23+FCFF!$C$24)/FCFF!$C$26 -> 7944.5739 | C5: =(FCFF!$C$10/(1+$A5)^1+FCFF!$D$10/(1+$A5)^2+FCFF!$E$10/(1+$A5)^3+FCFF!$F$10/(1+$A5)^4+FCFF!$G$10/(1+$A5)^5+(FCFF!$G$10*(1+C$4)/($A5-C$4))/(1+$A5)^5+FCFF!$C$22+FCFF!$C$23+FCFF!$C$24)/FCFF!$C$26 -> 9188.5108 | D5: =(FCFF!$C$10/(1+$A5)^1+FCFF!$D$10/(1+$A5)^2+FCFF!$E$10/(1+$A5)^3+FCFF!$F$10/(1+$A5)^4+FCFF!$G$10/(1+$A5)^5+(FCFF!$G$10*(1+D$4)/($A5-D$4))/(1+$A5)^5+FCFF!$C$22+FCFF!$C$23+FCFF!$C$24)/FCFF!$C$26 -> 11054.416 | E5: =(FCFF!$C$10/(1+$A5)^1+FCFF!$D$10/(1+$A5)^2+FCFF!$E$10/(1+$A5)^3+FCFF!$F$10/(1+$A5)^4+FCFF!$G$10/(1+$A5)^5+(FCFF!$G$10*(1+E$4)/($A5-E$4))/(1+$A5)^5+FCFF!$C$22+FCFF!$C$23+FCFF!$C$24)/FCFF!$C$26 -> 14164.258
A6: 0.1 | B6: =(FCFF!$C$10/(1+$A6)^1+FCFF!$D$10/(1+$A6)^2+FCFF!$E$10/(1+$A6)^3+FCFF!$F$10/(1+$A6)^4+FCFF!$G$10/(1+$A6)^5+(FCFF!$G$10*(1+B$4)/($A6-B$4))/(1+$A6)^5+FCFF!$C$22+FCFF!$C$23+FCFF!$C$24)/FCFF!$C$26 -> 6840.7693 | C6: =(FCFF!$C$10/(1+$A6)^1+FCFF!$D$10/(1+$A6)^2+FCFF!$E$10/(1+$A6)^3+FCFF!$F$10/(1+$A6)^4+FCFF!$G$10/(1+$A6)^5+(FCFF!$G$10*(1+C$4)/($A6-C$4))/(1+$A6)^5+FCFF!$C$22+FCFF!$C$23+FCFF!$C$24)/FCFF!$C$26 -> 7697.4235 | D6: =(FCFF!$C$10/(1+$A6)^1+FCFF!$D$10/(1+$A6)^2+FCFF!$E$10/(1+$A6)^3+FCFF!$F$10/(1+$A6)^4+FCFF!$G$10/(1+$A6)^5+(FCFF!$G$10*(1+D$4)/($A6-D$4))/(1+$A6)^5+FCFF!$C$22+FCFF!$C$23+FCFF!$C$24)/FCFF!$C$26 -> 8896.7394 | E6: =(FCFF!$C$10/(1+$A6)^1+FCFF!$D$10/(1+$A6)^2+FCFF!$E$10/(1+$A6)^3+FCFF!$F$10/(1+$A6)^4+FCFF!$G$10/(1+$A6)^5+(FCFF!$G$10*(1+E$4)/($A6-E$4))/(1+$A6)^5+FCFF!$C$22+FCFF!$C$23+FCFF!$C$24)/FCFF!$C$26 -> 10695.713
A7: 0.10232198 | B7: =(FCFF!$C$10/(1+$A7)^1+FCFF!$D$10/(1+$A7)^2+FCFF!$E$10/(1+$A7)^3+FCFF!$F$10/(1+$A7)^4+FCFF!$G$10/(1+$A7)^5+(FCFF!$G$10*(1+B$4)/($A7-B$4))/(1+$A7)^5+FCFF!$C$22+FCFF!$C$23+FCFF!$C$24)/FCFF!$C$26 -> 6628.5055 | C7: =(FCFF!$C$10/(1+$A7)^1+FCFF!$D$10/(1+$A7)^2+FCFF!$E$10/(1+$A7)^3+FCFF!$F$10/(1+$A7)^4+FCFF!$G$10/(1+$A7)^5+(FCFF!$G$10*(1+C$4)/($A7-C$4))/(1+$A7)^5+FCFF!$C$22+FCFF!$C$23+FCFF!$C$24)/FCFF!$C$26 -> 7420.0588 | D7: =(FCFF!$C$10/(1+$A7)^1+FCFF!$D$10/(1+$A7)^2+FCFF!$E$10/(1+$A7)^3+FCFF!$F$10/(1+$A7)^4+FCFF!$G$10/(1+$A7)^5+(FCFF!$G$10*(1+D$4)/($A7-D$4))/(1+$A7)^5+FCFF!$C$22+FCFF!$C$23+FCFF!$C$24)/FCFF!$C$26 -> 8514.1823 | E7: =(FCFF!$C$10/(1+$A7)^1+FCFF!$D$10/(1+$A7)^2+FCFF!$E$10/(1+$A7)^3+FCFF!$F$10/(1+$A7)^4+FCFF!$G$10/(1+$A7)^5+(FCFF!$G$10*(1+E$4)/($A7-E$4))/(1+$A7)^5+FCFF!$C$22+FCFF!$C$23+FCFF!$C$24)/FCFF!$C$26 -> 10125.353
A8: 0.11 | B8: =(FCFF!$C$10/(1+$A8)^1+FCFF!$D$10/(1+$A8)^2+FCFF!$E$10/(1+$A8)^3+FCFF!$F$10/(1+$A8)^4+FCFF!$G$10/(1+$A8)^5+(FCFF!$G$10*(1+B$4)/($A8-B$4))/(1+$A8)^5+FCFF!$C$22+FCFF!$C$23+FCFF!$C$24)/FCFF!$C$26 -> 6015.2211 | C8: =(FCFF!$C$10/(1+$A8)^1+FCFF!$D$10/(1+$A8)^2+FCFF!$E$10/(1+$A8)^3+FCFF!$F$10/(1+$A8)^4+FCFF!$G$10/(1+$A8)^5+(FCFF!$G$10*(1+C$4)/($A8-C$4))/(1+$A8)^5+FCFF!$C$22+FCFF!$C$23+FCFF!$C$24)/FCFF!$C$26 -> 6634.87 | D8: =(FCFF!$C$10/(1+$A8)^1+FCFF!$D$10/(1+$A8)^2+FCFF!$E$10/(1+$A8)^3+FCFF!$F$10/(1+$A8)^4+FCFF!$G$10/(1+$A8)^5+(FCFF!$G$10*(1+D$4)/($A8-D$4))/(1+$A8)^5+FCFF!$C$22+FCFF!$C$23+FCFF!$C$24)/FCFF!$C$26 -> 7461.0684 | E8: =(FCFF!$C$10/(1+$A8)^1+FCFF!$D$10/(1+$A8)^2+FCFF!$E$10/(1+$A8)^3+FCFF!$F$10/(1+$A8)^4+FCFF!$G$10/(1+$A8)^5+(FCFF!$G$10*(1+E$4)/($A8-E$4))/(1+$A8)^5+FCFF!$C$22+FCFF!$C$23+FCFF!$C$24)/FCFF!$C$26 -> 8617.7462
A9: 0.12 | B9: =(FCFF!$C$10/(1+$A9)^1+FCFF!$D$10/(1+$A9)^2+FCFF!$E$10/(1+$A9)^3+FCFF!$F$10/(1+$A9)^4+FCFF!$G$10/(1+$A9)^5+(FCFF!$G$10*(1+B$4)/($A9-B$4))/(1+$A9)^5+FCFF!$C$22+FCFF!$C$23+FCFF!$C$24)/FCFF!$C$26 -> 5375.0799 | C9: =(FCFF!$C$10/(1+$A9)^1+FCFF!$D$10/(1+$A9)^2+FCFF!$E$10/(1+$A9)^3+FCFF!$F$10/(1+$A9)^4+FCFF!$G$10/(1+$A9)^5+(FCFF!$G$10*(1+C$4)/($A9-C$4))/(1+$A9)^5+FCFF!$C$22+FCFF!$C$23+FCFF!$C$24)/FCFF!$C$26 -> 5840.0457 | D9: =(FCFF!$C$10/(1+$A9)^1+FCFF!$D$10/(1+$A9)^2+FCFF!$E$10/(1+$A9)^3+FCFF!$F$10/(1+$A9)^4+FCFF!$G$10/(1+$A9)^5+(FCFF!$G$10*(1+D$4)/($A9-D$4))/(1+$A9)^5+FCFF!$C$22+FCFF!$C$23+FCFF!$C$24)/FCFF!$C$26 -> 6437.8588 | E9: =(FCFF!$C$10/(1+$A9)^1+FCFF!$D$10/(1+$A9)^2+FCFF!$E$10/(1+$A9)^3+FCFF!$F$10/(1+$A9)^4+FCFF!$G$10/(1+$A9)^5+(FCFF!$G$10*(1+E$4)/($A9-E$4))/(1+$A9)^5+FCFF!$C$22+FCFF!$C$23+FCFF!$C$24)/FCFF!$C$26 -> 7234.943
A12: Base-case WACC | B12: =WACC!C23 -> 0.10232198
A13: Base-case terminal growth | B13: =FCFF!C17 -> 0.05
A14: Terminal value / Enterprise value | B14: =FCFF!C19/FCFF!C20 -> 0.83251346
A16: Note | B16: The DCF is highly sensitive to WACC and terminal growth; use the sensitivity table rather than relying on a single point estimate.
